<?xml version="1.0"?>
<robot name="hopper">

<!-- Material definitions -->
<material name="black">
<color rgba="0.3 0 0 0.7"/>
</material>

<material name="blue">
<color rgba="0 0 0.8 1"/>
</material>

<material name="yellow">
<color rgba="0.3 0.3 0 0.7"/>
</material>
<material name="red">
<color rgba="1 0 0 1"/>
</material>

<material name="white">
<color rgba="1 1 1 1"/>
</material>

  <!-- Base Frame of Hopper -->
<link name="body">
<visual>     
<geometry>
<cylinder length="0.02" radius="0.15"/>
</geometry>
<origin rpy="0 0 0" xyz="0 0 0"/>
<material name="blue"/>
</visual>
<collision>
<origin rpy="0 0 0" xyz="0 0 0"/>
<geometry>
<cylinder length="0.01" radius="0.12"/>
</geometry>
</collision>
<material name="blue"/>
<inertial>
<mass value="0.00"/>
<inertia ixx="0.000" ixy="0.0" ixz="0.0" iyy="0.000" iyz="0.0" izz="0"/>
</inertial>
</link>

<link name="base_link1">
<visual>
<geometry>
  <box size="0.2 0.01 0.01"/>
</geometry>
<origin xyz="0 0.095 0"/>
<material name="yellow"/>
</visual>
<collision>
<geometry>
  <box size="0.2 0.01 0.01"/>
</geometry>
<origin xyz="0 0.095 0"/>
</collision>
<inertial>
<mass value="0.15"/>
<origin xyz="0 0.095 0"/>
<inertia ixx="2.499999e-06" ixy="0.0" ixz="0.0" iyy="0.0005012497995" iyz="0.0" izz="0.0005012497995"/>
</inertial>
</link>
<link name="base_link2">
<visual>
<geometry>
  <box size="0.2 0.01 0.01"/>
</geometry>
<origin xyz="0 -0.095 0"/>
<material name="blue"/>
</visual>
<collision>
<geometry>
  <box size="0.2 0.01 0.01"/>
</geometry>
<origin xyz="0 -0.095 0"/>
</collision>
<inertial>
<mass value="0.15"/>
<origin xyz="0 -0.095 0"/>
<inertia ixx="2.499999e-06" ixy="0.0" ixz="0.0" iyy="0.0005012497995" iyz="0.0" izz="0.0005012497995"/>
</inertial>
</link>
<joint name="base1_to_base2" type="fixed">
<parent link="base_link1"/>
<child link="base_link2"/>
</joint>
<link name="base_link3">
<visual>
<geometry>
  <box size="0.01 0.18 0.01"/>
</geometry>
<origin xyz="0.095 0 0"/>
<material name="blue"/>
</visual>
<collision>
<geometry>
  <box size="0.01 0.18 0.01"/>
</geometry>
<origin xyz="0.095 0 0"/>
</collision>
<inertial>
<mass value="0.15"/>
<origin xyz="0.095 0 0"/>
<inertia ixx="0.0004062498375" ixy="0.0" ixz="0.0" iyy="2.499999e-06" iyz="0.0" izz="0.0004062498375"/>
</inertial>
</link>
<joint name="base1_to_base3" type="fixed">
<parent link="base_link1"/>
<child link="base_link3"/>
</joint>
<link name="base_link4">
<visual>
<geometry>
  <box size="0.01 0.18 0.01"/>
</geometry>
<origin xyz="-0.095 0 0"/>
<material name="blue"/>
</visual>
<collision>
<geometry>
  <box size="0.01 0.18 0.01"/>
</geometry>
<origin xyz="-0.095 0 0"/>
</collision>
<inertial>
<mass value="0.15"/>
<origin xyz="-0.095 0 0"/>
<inertia ixx="0.0004062498375" ixy="0.0" ixz="0.0" iyy="2.499999e-06" iyz="0.0" izz="0.0004062498375"/>
</inertial>
</link>
<joint name="base1_to_base4" type="fixed">
<parent link="base_link1"/>
<child link="base_link4"/>
</joint>

<joint name="body_to_base1" type="fixed">
<parent link="base_link1"/>
<child link="body"/>
</joint>


  <!-- Mid Frame of Hopper -->
<link name="mid_link1">
<visual>
<geometry>
<box size="0.01 0.03 0.01"/>
</geometry>
<origin xyz="0.085 0 0"/>
<material name="red"/>
</visual>
<collision>
<geometry>
<box size="0.01 0.03 0.01"/>
</geometry>
<origin xyz="0.085 0 0"/>
</collision>
<inertial>
<mass value="0.15"/>
<origin xyz="0.085 0 0"/>
<inertia ixx="1.2499995e-05" ixy="0.0" ixz="0.0" iyy="2.499999e-06" iyz="0.0" izz="1.2499995e-05"/>
</inertial>
</link>
<joint name="hip_roll" type="revolute">
<axis xyz="-1 0 0"/>
<limit effort="1000.0" lower="-1.548" upper="1.548" velocity="5"/>
<origin rpy="0 0 0" xyz="0 0 0"/>
<parent link="base_link3"/>
<child link="mid_link1"/>
</joint>
<link name="mid_link2">
<visual>
<geometry>
<box size="0.01 0.03 0.01"/>
</geometry>
<origin xyz="-0.085 0 0"/>
<material name="black"/>
</visual>
<collision>
<geometry>
<box size="0.01 0.03 0.01"/>
</geometry>
<origin xyz="-0.085 0 0"/>
</collision>
<inertial>
<mass value="0.15"/>
<origin xyz="-0.085 0 0"/>
<inertia ixx="1.2499995e-05" ixy="0.0" ixz="0.0" iyy="2.499999e-06" iyz="0.0" izz="1.2499995e-05"/>
</inertial>
</link>
<joint name="mid1_mid2_joint" type="fixed">
<parent link="mid_link1"/>
<child link="mid_link2"/>
</joint>
<link name="mid_link3">
<visual>
<geometry>
<box size="0.18 0.01 0.01"/>
</geometry>
<origin xyz="0 0.02 0"/>
<material name="red"/>
</visual>
<collision>
<geometry>
<box size="0.18 0.01 0.01"/>
</geometry>
<origin xyz="0 0.02 0"/>
</collision>
<inertial>
<mass value="0.15"/>
<origin xyz="0 0.02 0"/>
<inertia ixx="2.499999e-06" ixy="0.0" ixz="0.0" iyy="0.0004062498375" iyz="0.0" izz="0.0004062498375"/>
</inertial>
</link>
<joint name="mid1_mid3_joint" type="fixed">
<parent link="mid_link1"/>
<child link="mid_link3"/>
</joint>
<link name="mid_link4">
<visual>
<geometry>
<box size="0.18 0.01 0.01"/>
</geometry>
<origin xyz="0 -0.02 0"/>
<material name="black"/>
</visual>
<collision>
<geometry>
<box size="0.18 0.01 0.01"/>
</geometry>
<origin xyz="0 -0.02 0"/>
</collision>
<inertial>
<mass value="0.15"/>
<origin xyz="0 -0.02 0"/>
<inertia ixx="2.499999e-06" ixy="0.0" ixz="0.0" iyy="0.0004062498375" iyz="0.0" izz="0.0004062498375"/>
</inertial>
</link>
<joint name="mid1_mid4_joint" type="fixed">
<parent link="mid_link1"/>
<child link="mid_link4"/>
</joint>
<link name="cylinder">
<visual>
<geometry>
<cylinder length="0.02" radius="0.01"/>
</geometry>
<origin xyz="0 0 0"/>
<material name="white"/>
</visual>
<collision>
<geometry>
<cylinder length="0.02" radius="0.01"/>
</geometry>
<origin xyz="0 0 0"/>
</collision>
<inertial>
<mass value="0.1"/>
<origin xyz="0 0 0"/>
<inertia ixx="5.833331e-06" ixy="0.0" ixz="0.0" iyy="5.833331e-06" iyz="0.0" izz="5e-06"/>
</inertial>
</link>
<joint name="hip_pitch" type="revolute">
<axis xyz="0 -1 0"/>
<limit effort="1000.0" lower="-1.548" upper="1.548" velocity="5"/>
<origin rpy="0 0 0" xyz="0 0 0"/>
<parent link="mid_link3"/>
<child link="cylinder"/>
</joint>
<link name="leg_tip">
<visual>
<geometry>
<sphere radius="0.01"/>
</geometry>
<origin xyz="0 0 0"/>
<material name="yellow"/>
</visual>
<collision>
<geometry>
<sphere radius="0.01"/>
</geometry>
<origin xyz="0 0 0"/>
</collision>
<inertial>
<mass value="0.02"/>
<origin xyz="0 0 0"/>
<inertia ixx="8e-07" ixy="0.0" ixz="0.0" iyy="8e-07" iyz="0.0" izz="8e-07"/>
</inertial>
</link>

<link name="shin_link">
<visual>
<material name="white"/>
<origin rpy="0 0 0" xyz="0 0 0.25"/>
<geometry>
<cylinder length="0.2" radius="0.003"/>
</geometry>
</visual>
<inertial>
<mass value="0.000"/>
<inertia ixx="0" ixy="0.0" ixz="0.0" iyy="0" iyz="0.0" izz="0"/>
</inertial>
<collision>
<origin rpy="0 0 0" xyz="0 0 0.25"/>
<geometry>
<cylinder length="0.2" radius="0.003"/>
</geometry>
</collision>
</link>

<joint name="ankle" type="fixed">
<origin rpy="0 0 0" xyz="0.0 0.0 -0.15"/>
<parent link="leg_tip"/>
<child link="shin_link"/>
</joint>

<joint name="leg_spring" type="prismatic">
<axis xyz="0 0 1"/>
<limit effort="1000.0" lower="-0.35" upper="0.805" velocity="10"/>
<origin rpy="0 0 0" xyz="0 0 -0.15"/>
<parent link="cylinder"/>
<child link="leg_tip"/>
<dynamics damping="2"/>
</joint>
</robot>
