<?xml version="1.0"?>
<robot name="hopper">

<!-- Material definitions -->
<material name="blue">
<color rgba="0 0 0.8 1"/>
</material>

<material name="white">
<color rgba="1 1 1 1"/>
</material>

<material name="red">
<color rgba="1 0 0 1"/>
</material>

<!-- 2D constraints to make the robot planarized -->
<link name="world">
<inertial>
<mass value="0"/>
<inertia ixx="0.2125" ixy="-0.005" ixz="0.0225" iyy="0.205" iyz="0.045" izz="0.0125"/>
<origin rpy="0 0 0" xyz="0 0 0"/>
</inertial>
</link>

<link name="x_prismatic">
<inertial>
<mass value="0.01"/>
<inertia ixx="0.2125" ixy="-0.005" ixz="0.0225" iyy="0.205" iyz="0.045" izz="0.0125"/>
<origin rpy="0 0 0" xyz="0 0 0"/>
</inertial>
</link>

<link name="z_prismatic">
<inertial>
<mass value="0.01"/>
<inertia ixx="0.2125" ixy="-0.005" ixz="0.0225" iyy="0.205" iyz="0.045" izz="0.0125"/>
<origin rpy="0 0 0" xyz="0 0 0"/>
</inertial>
</link>

<joint name="x_to_world" type="prismatic">
<parent link="world"/>
<child link="x_prismatic"/>
<axis xyz="1 0 0"/>
<limit effort="0.0" lower="1" upper="-1" velocity="1000.0"/>
<origin rpy="0 0 0" xyz="0 0 0"/>
</joint>

<joint name="z_to_y" type="prismatic">
<parent link="x_prismatic"/>
<child link="z_prismatic"/>
<axis xyz="0 0 1"/>
<limit effort="0.0" lower="1" upper="-1" velocity="1000.0"/>
<origin rpy="0 0 0" xyz="0 0 0"/>
</joint>

<joint name="body_to_z" type="continuous">
<parent link="z_prismatic"/>
<child link="body"/>
<axis xyz="0 1 0"/>
<origin rpy="0 0 0" xyz="0 0 0"/>
</joint>


<!-- The robot links definition -->
<link name="body">
<visual>     
<geometry>
<cylinder length="1.0" radius="0.05"/>
</geometry>
<origin rpy="0 1.57075 0" xyz="0 0 0"/>
<material name="blue"/>
</visual>
<collision>
<origin rpy="0 1.57075 0" xyz="0 0 0"/>
<geometry>
<cylinder length="1.0" radius="0.05"/>
</geometry>
</collision>
<material name="blue"/>
<inertial>
<mass value="100"/>
<inertia ixx="8.4" ixy="0.0" ixz="0.0" iyy="8.4" iyz="0.0" izz="5e+01"/>
</inertial>
</link>

<link name="hip_link">
<visual>
<material name="white"/>
<origin rpy="0 0 0" xyz="0 0 0"/>
<geometry>
<cylinder length="0.3" radius="0.05"/>
</geometry>
</visual>
<inertial>
<mass value="1"/>
<inertia ixx="0.0079" ixy="0.0" ixz="0.0" iyy="0.0079" iyz="0.0" izz="0.045"/>
</inertial>
<collision>
<origin rpy="0 0 0" xyz="0 0 0"/>
<geometry>
<cylinder length="0.3" radius="0.05"/>
</geometry>
</collision>
</link>

<link name="shin_link">
<visual>
<material name="white"/>
<origin rpy="0 0 0" xyz="0 0 0"/>
<geometry>
<cylinder length="1.0" radius="0.005"/>
</geometry>
</visual>
<inertial>
<mass value="1"/>
<inertia ixx="0.083" ixy="0.0" ixz="0.0" iyy="0.083" iyz="0.0" izz="0.5"/>
</inertial>
<collision>
<origin rpy="0 0 0" xyz="0 0 0"/>
<geometry>
<cylinder length="1.0" radius="0.005"/>
</geometry>
</collision>
</link>

<link name="foot">
<visual>
<material name="red"/>
<origin rpy="0 0 0" xyz="0 0 0"/>
<geometry>
<sphere radius="0.06"/>
</geometry>
</visual>
<inertial>
<mass value="1"/>
<inertia ixx="0.0014" ixy="0.0" ixz="0.0" iyy="0.0014" iyz="0.0" izz="0.0014"/>
</inertial>      
<collision>
<origin rpy="0 0 0" xyz="0 0 0"/>
<geometry>
<sphere radius="0.06"/>
</geometry>
</collision>
</link>

<!-- The robot joints definition -->
<joint name="hip" type="continuous">
<origin rpy="0 0 0" xyz="0 0 0"/>
<parent link="body"/>
<child link="hip_link"/>
<axis xyz="0.0 1.0 0.0"/>
</joint>

<joint name="leg" type="prismatic">
<parent link="hip_link"/>
<child link="shin_link"/>
<axis xyz="0.0 0.0 1.0"/>
<limit effort="1000.0" lower="-10000.0" upper="10000.0" velocity="1000.0"/>
</joint>

<joint name="foot" type="fixed">
<origin rpy="0 0 0" xyz="0.0 0.0 -0.5"/>
<parent link="shin_link"/>
<child link="foot"/>
</joint>

</robot>  
